Workbook

Sheet Sheet1
C2: ÎNTREBĂRI - SEPTEMBRIE 2024 | E2: legea lui Ohm, legile lui Kirchhoff, circuit RLC, conexiuni stea, triunghi transformator, motor, masina sincrona asincrona
B4: ELECTROTEHNICĂ, MAŞINI ŞI REŢELE ELECTRICE | M4: Total | N4: Parcurs | O4: Ramas
M5: 861 | N5: =COUNTA(G7:G867) -> 1 | O5: =M5-N5 -> 860
A6: Nr. | B6: SEPTEMBRIE 2024 Enunt | C6: Varianta a | D6: Varianta b | E6: Varianta c | G6: Raspuns | H6: verif | I6: var a | J6: var b | K6: var c | N6: =N5/M5 -> 0.0011614402
A7: 1 | B7: Atunci când se compensează energia electrica reactiva prin baterii de condensatoare, tensiunea în reţeaua electrica: | C7: scade | D7: nu se modifica | E7: creste | G7: c | H7: =IF(G7=0,"NECOMPLETAT",IF(OR(G7=I7,G7=J7,G7=K7),"CORECT","GRESIT")) -> CORECT | I7: …...... | J7: …...... | K7: c
A8: 2 | B8: Bobinele de stingere din staţiile electrice de transformare sunt echipamente pentru: | C8: compensarea factorului de putere | D8: dotări PSI | E8: compensarea curenţilor capacitivi | H8: =IF(G8=0,"NECOMPLETAT",IF(OR(G8=I8,G8=J8,G8=K8),"CORECT","GRESIT")) -> NECOMPLETAT | I8: …...... | J8: …...... | K8: c
A9: 3 | B9: Câmpul magnetic poate fi produs: | C9: numai de magneţi permanenţi | D9: numai de electromagneţi | E9: de magneţi permanenţi si de electromagneţi | H9: =IF(G9=0,"NECOMPLETAT",IF(OR(G9=I9,G9=J9,G9=K9),"CORECT","GRESIT")) -> NECOMPLETAT | I9: …...... | J9: …...... | K9: c
A10: 4 | B10: 3 condensatoare având capacitatea C1=100 μF, C2=50 μF, C3=100 μF legate în paralel, au capacitatea echivalentă. | C10: 25 μF | D10: 250 μF | E10: 50 μF | H10: =IF(G10=0,"NECOMPLETAT",IF(OR(G10=I10,G10=J10,G10=K10),"CORECT","GRESIT")) -> NECOMPLETAT | I10: …...... | J10: b | K10: …......
A11: 5 | B11: A doua teoremă a lui Kirchhoff, pentru o reţea electrică cu N noduri şi L laturi (L diferit de N), ne furnizează, pentru analiza unui circuit electric: | C11: L+N-1 ecuaţii distincte | D11: L-N +1 ecuaţii distincte | E11: N-L+1 ecuaţii distincte | H11: =IF(G11=0,"NECOMPLETAT",IF(OR(G11=I11,G11=J11,G11=K11),"CORECT","GRESIT")) -> NECOMPLETAT | I11: …...... | J11: b | K11: …......
A12: 6 | B12: AAR se utilizează în scopul: | C12: limitării curenţilor de scurtcircuit; | D12: creşterii continuităţii în alimentare; | E12: reducerii pierderilor de energie pe linii. | H12: =IF(G12=0,"NECOMPLETAT",IF(OR(G12=I12,G12=J12,G12=K12),"CORECT","GRESIT")) -> NECOMPLETAT | I12: …...... | J12: b | K12: …......
A13: 7 | B13: Alunecarea s a unui motor asincron are valori: | C13: cuprinse între 1 si 0 | D13: cuprinse între -1 si 0 | E13: de regulă, mai mari decât 1 | H13: =IF(G13=0,"NECOMPLETAT",IF(OR(G13=I13,G13=J13,G13=K13),"CORECT","GRESIT")) -> NECOMPLETAT | I13: a | J13: …...... | K13: …......
A14: 8 | B14: Aparatul notat cu C pe desenul de mai sus al unei celule prefabricate de medie tensiune de tip închis, reprezintă un: | C14: întreruptor; | D14: transformator de curent; | E14: transformator de tensiune | H14: =IF(G14=0,"NECOMPLETAT",IF(OR(G14=I14,G14=J14,G14=K14),"CORECT","GRESIT")) -> NECOMPLETAT | I14: …...... | J14: b | K14: …......
A15: 9 | B15: Care element nu se foloseşte la reglarea tensiunii în reţelele electrice: | C15: bobina de compensare | D15: transformatorul | E15: rezistorul | H15: =IF(G15=0,"NECOMPLETAT",IF(OR(G15=I15,G15=J15,G15=K15),"CORECT","GRESIT")) -> NECOMPLETAT | I15: …...... | J15: …...... | K15: c
A16: 10 | B16: Cele mai des utilizate pentru serviciile interne ale centralelor electrice sunt: | C16: motoarele de curent continuu | D16: motoarele sincrone | E16: motoarele asincrone | H16: =IF(G16=0,"NECOMPLETAT",IF(OR(G16=I16,G16=J16,G16=K16),"CORECT","GRESIT")) -> NECOMPLETAT | I16: …...... | J16: …...... | K16: c
A17: 11 | B17: Bobinele pentru limitarea curenţilor de scurtcircuit au: | C17: rezistenta mare | D17: inductanţa mare | E17: inductanţa mica | H17: =IF(G17=0,"NECOMPLETAT",IF(OR(G17=I17,G17=J17,G17=K17),"CORECT","GRESIT")) -> NECOMPLETAT | I17: …...... | J17: b | K17: …......
A18: 12 | B18: Câmpul electrostatic este descris | C18: prin: intensitatea câmpului electric | D18: numai prin inducţia electrică | E18: inducţia magnetică | H18: =IF(G18=0,"NECOMPLETAT",IF(OR(G18=I18,G18=J18,G18=K18),"CORECT","GRESIT")) -> NECOMPLETAT | I18: a | J18: …...... | K18: …......
A19: 13 | B19: Comparativ cu cele uscate, transformatoarele imersate prezintă : | C19: o bună rezistenţă la foc; | D19: risc crescut de poluare acustică a mediului ambiant; | E19: necesitatea unor amenajări speciale la instalare | H19: =IF(G19=0,"NECOMPLETAT",IF(OR(G19=I19,G19=J19,G19=K19),"CORECT","GRESIT")) -> NECOMPLETAT | I19: …...... | J19: …...... | K19: c
... A28: 22 | B28: Care dintre relaţiile următoare este adevărată: | C28: inducţia electrică = permitivitatea x intensitatea câmpului electric | D28: inducţia electrică = intensitatea câmpului electric/ permitivitate | E28: inducţia electrică=sarcina x intensitatea câmpului electric | H28: =IF(G28=0,"NECOMPLETAT",IF(OR(G28=I28,G28=J28,G28=K28),"CORECT","GRESIT")) -> NECOMPLETAT | I28: a | J28: …...... | K28: …......
A29: 23 | B29: Care dintre schemele alăturate permite obţinerea a două circuite de cuplă diagonală (cruce cu întreruptor ) ? | H29: =IF(G29=0,"NECOMPLETAT",IF(OR(G29=I29,G29=J29,G29=K29),"CORECT","GRESIT")) -> NECOMPLETAT | I29: a | J29: …...... | K29: …......
A30: 24 | B30: Care dintre schemele alăturate permite obţinerea a două circuite de cuplă longitudinală ( cu întreruptor) ? | H30: =IF(G30=0,"NECOMPLETAT",IF(OR(G30=I30,G30=J30,G30=K30),"CORECT","GRESIT")) -> NECOMPLETAT | I30: a | J30: …...... | K30: …......
A31: 25 | B31: Care dintre schemele alăturate permite obţinerea a două circuite de cuplă transversală ( cu întreruptor) ? | H31: =IF(G31=0,"NECOMPLETAT",IF(OR(G31=I31,G31=J31,G31=K31),"CORECT","GRESIT")) -> NECOMPLETAT | I31: …...... | J31: …...... | K31: c
A32: 26 | B32: Utilizarea unei cuple cu functiuni multiple se prefera atunci cand dorim | C32: scurtarea duratei manevrelor | D32: cresterea continuitatii in alimentare | E32: reducerea investitiei in echiparea statiei. | H32: =IF(G32=0,"NECOMPLETAT",IF(OR(G32=I32,G32=J32,G32=K32),"CORECT","GRESIT")) -> NECOMPLETAT | I32: …...... | J32: b | K32: …......
A33: 27 | B33: Care este energia consumata de o rezistenta electrica r = 10 Ω, prin care trece un curent de 2 A timp de 10 ore: | C33: 200 Wh | D33: 400 Wh | E33: 800 Wh | H33: =IF(G33=0,"NECOMPLETAT",IF(OR(G33=I33,G33=J33,G33=K33),"CORECT","GRESIT")) -> NECOMPLETAT | I33: …...... | J33: b | K33: …......
A34: 28 | B34: Ce posibilităţi de limitare a curenţilor de scurtcirciut sunt de preferat pentru schema de mai sus ? | C34: reducerea t.e.m., acţionând asupra circuitului de excitaţie al generatorului; | D34: mărirea reactanţei schemei de alimentare între sursă şi locul de defect; | E34: creşterea capacităţii de rupere a întreruptoarelor. | H34: =IF(G34=0,"NECOMPLETAT",IF(OR(G34=I34,G34=J34,G34=K34),"CORECT","GRESIT")) -> NECOMPLETAT | I34: …...... | J34: b | K34: …......
A35: 29 | B35: Curentul electric alternativ poate fi produs numai prin fenomene: | C35: termice | D35: chimice | E35: de inducţie electromagnetică | H35: =IF(G35=0,"NECOMPLETAT",IF(OR(G35=I35,G35=J35,G35=K35),"CORECT","GRESIT")) -> NECOMPLETAT | I35: …...... | J35: …...... | K35: c
A36: 30 | B36: Scheme cu un sistem de bare colectoare şi un întreruptor pe circuit sunt folosite | C36: numai pentru staţii de conexiuni de 6 kV | D36: pentru toate treptele de tensiune din reţelele de distribuţie | E36: numai pentru staţii de conexiuni de medie tensiune până la 6o kV | H36: =IF(G36=0,"NECOMPLETAT",IF(OR(G36=I36,G36=J36,G36=K36),"CORECT","GRESIT")) -> NECOMPLETAT | I36: …...... | J36: b | K36: …......
A37: 31 | B37: Celulele prefabricate monobloc se caracterizează în principal prin: | C37: securitate ridicată a persoanelor; | D37: gamă largă de configuraţii ale schemei de conexiuni; | E37: eliminarea totală a posibilităţii de producere a unui scurtcircuit între faze | H37: =IF(G37=0,"NECOMPLETAT",IF(OR(G37=I37,G37=J37,G37=K37),"CORECT","GRESIT")) -> NECOMPLETAT | I37: a | J37: …...... | K37: …......
A38: 32 | B38: Circulaţia câmpului magnetic pe un contur închis este egală cu: | C38: suma algebrică a curenţilor care străbat conturul | D38: zero | E38: suma căderilor de tensiune de-a lungul conturului | H38: =IF(G38=0,"NECOMPLETAT",IF(OR(G38=I38,G38=J38,G38=K38),"CORECT","GRESIT")) -> NECOMPLETAT | I38: a | J38: …...... | K38: …......
A39: 33 | B39: Comparativ cu cele imersate, transformatoarele uscate prezintă : | C39: o bună rezistenţă la foc; | D39: risc redus de poluare acustică a mediului ambiant; | E39: necesitatea unor amenajări speciale la instalare | H39: =IF(G39=0,"NECOMPLETAT",IF(OR(G39=I39,G39=J39,G39=K39),"CORECT","GRESIT")) -> NECOMPLETAT | I39: a | J39: …...... | K39: …......
A40: 34 | B40: Daca la un circuit al unei staţii de 6 sau 20 kV care funcţionează cu neutrul izolat apare o punere monofazatã netã la pământ, tensiunea fata de pământ a celorlalte doua faze: | C40: scade de 1,41 ori | D40: rămâne constanta | E40: creste de 1,73 ori | H40: =IF(G40=0,"NECOMPLETAT",IF(OR(G40=I40,G40=J40,G40=K40),"CORECT","GRESIT")) -> NECOMPLETAT | I40: …...... | J40: …...... | K40: c
A41: 35 | B41: Compartimentarea unei celule electrice se utilizează | C41: în scopul evitării extinderii avariilor; | D41: numai în scopul protejării personalului de exploatare; | E41: protecţiei la supratensiuni | H41: =IF(G41=0,"NECOMPLETAT",IF(OR(G41=I41,G41=J41,G41=K41),"CORECT","GRESIT")) -> NECOMPLETAT | I41: a | J41: …...... | K41: …......
A42: 36 | B42: Compartimentul notat cu 2 pe desenul de mai sus al unei celule prefabricate de medie tensiune de tip închis, reprezintă: | C42: compartimentul de legătură cu reţeaua electrică; | D42: compartimentul aparatajului de comutaţie; | E42: compartimentul circuitelor secundare. | H42: =IF(G42=0,"NECOMPLETAT",IF(OR(G42=I42,G42=J42,G42=K42),"CORECT","GRESIT")) -> NECOMPLETAT | I42: …...... | J42: b | K42: …......
A43: 37 | B43: Compartimentul notat cu 3 pe desenul de mai sus al unei celule prefabricate de medie tensiune de tip închis, reprezintă: | C43: compartimentul de legătură cu reţeaua electrică; | D43: compartimentul aparatajului de comutaţie; | E43: compartimentul circuitelor secundare. | H43: =IF(G43=0,"NECOMPLETAT",IF(OR(G43=I43,G43=J43,G43=K43),"CORECT","GRESIT")) -> NECOMPLETAT | I43: a | J43: …...... | K43: …......
... A77: 71 | B77: Extinderea domeniului de măsurare la voltmetre se realizează cu: | C77: shunturi | D77: rezistente adiţionale | E77: condensatoare montate în paralel | H77: =IF(G77=0,"NECOMPLETAT",IF(OR(G77=I77,G77=J77,G77=K77),"CORECT","GRESIT")) -> NECOMPLETAT | I77: …...... | J77: b | K77: …......
A78: 72 | B78: Factorul de atenuare al unui circuit format dintr-un rezistor de rezistenţă R înseriat cu o bobină de inductanţă L, alimentate de o tensiune electromotoare constantă este egal cu: | C78: R/L | D78: L/R | E78: 1 | H78: =IF(G78=0,"NECOMPLETAT",IF(OR(G78=I78,G78=J78,G78=K78),"CORECT","GRESIT")) -> NECOMPLETAT | I78: …...... | J78: b | K78: …......
A79: 73 | B79: Fluxul electric total, produs de o sarcină electrică de valoare q printr-o suprafaţă închisă care o înconjoară, este egal cu: | C79: valoarea numerică 2q | D79: valoarea numerică q | E79: valoarea numerică q/2 | H79: =IF(G79=0,"NECOMPLETAT",IF(OR(G79=I79,G79=J79,G79=K79),"CORECT","GRESIT")) -> NECOMPLETAT | I79: …...... | J79: b | K79: …......
A80: 74 | B80: Folosirea conductoarelor jumelate în construcţia LEA are ca scop principal: | C80: reducerea pierderilor Corona | D80: reducerea solicitărilor mecanice ale stâlpilor | E80: reducerea curenţilor de scurtcircuit | H80: =IF(G80=0,"NECOMPLETAT",IF(OR(G80=I80,G80=J80,G80=K80),"CORECT","GRESIT")) -> NECOMPLETAT | I80: a | J80: …...... | K80: …......
A81: 75 | B81: Formula de calcul a frecventei produsa în sistemul electroenergetic de un generator cu n [rot/min] si p perechi de poli este: | C81: f =n p / 60 | D81: f = 60 n / p | E81: f = 60 p / n | H81: =IF(G81=0,"NECOMPLETAT",IF(OR(G81=I81,G81=J81,G81=K81),"CORECT","GRESIT")) -> NECOMPLETAT | I81: a | J81: …...... | K81: …......
A82: 76 | B82: Formula e = B l v, unde e este tensiune electromotoare, B este inducţia magnetică, l este lungimea unui conductor, v este viteza de deplasare a acestuia, reprezintă o forma particulară a: | C82: teoremelor Biot-Savart | D82: legii inducţiei electromagnetice | E82: legii circuitului magnetic | H82: =IF(G82=0,"NECOMPLETAT",IF(OR(G82=I82,G82=J82,G82=K82),"CORECT","GRESIT")) -> NECOMPLETAT | I82: …...... | J82: b | K82: …......
A83: 77 | B83: Forţa care se exercită asupra unui conductor rectiliniu, parcurs de curentul i, aflat în câmpul de inducţie magnetică B se numeşte: | C83: forţă electromagnetică (Laplace) | D83: forţă electrodinamică | E83: forţă magnetomotoare | H83: =IF(G83=0,"NECOMPLETAT",IF(OR(G83=I83,G83=J83,G83=K83),"CORECT","GRESIT")) -> NECOMPLETAT | I83: a | J83: …...... | K83: …......
...

Sheet QUIZ
D2: ÎNTREBĂRI - SEPTEMBRIE 2024 | F2: legea lui Ohm, legile lui Kirchhoff, circuit RLC, conexiuni stea, triunghi transformator, motor, masina sincrona asincrona
C4: ELECTROTEHNICĂ, MAŞINI ŞI REŢELE ELECTRICE | N4: Total | O4: Parcurs | P4: Ramas
N5: 861 | O5: =COUNTA(I7:I31) -> 25 | P5: =N5-O5 -> 836
A6: Nr. | B6: Nr. | C6: SEPTEMBRIE 2024 Enunt | D6: Varianta a | E6: Varianta b | F6: Varianta c | I6: Raspuns | J6: verif | K6: var a | L6: var b | M6: var c | O6: =O5/N5 -> 0.029036005
A7: 1 | B7: {=_xlfn._xlws.FILTER(Sheet1!A6:K866,Sheet1!A6:A866=RANDBETWEEN(1,861),"Fatal ERROR, this PC will explode in about 1 minute")} -> 558 | C7: Legarea conductoarelor din cupru la aparate, maşini, elemente metalice fixe, se face (de regulă) prin strângere mecanică cu şuruburi în cazul conductoarelor cu secţiuni mai mici sau egale cu: | D7: 16 mmp | E7: 10 mmp | F7: 6 mmp | G7: 0 | H7: 0 | I7: NECOMPLETAT | J7: …...... | K7: b | L7: …......
A8: 2 | B8: {=_xlfn._xlws.FILTER(Sheet1!A7:K867,Sheet1!A7:A867=RANDBETWEEN(1,861),"Fatal ERROR, this PC will explode in about 1 minute")} -> 738 | C8: Calitatea de autoritate contractantă pentru concesionarea bunurilor proprietate publică sau privată a statului din domeniul energetic, precum şi pentru activităţile sau serviciile publice de interes naţional și general din domeniul energiei electrice o are | D8: Ministerul de resort | E8: ANRE - Autoritatea Naţională de Reglementare în domeniul Energiei | F8: ANRSC - Autoritatea Naţională de Reglementare in domeniul Serviciilor Comunale | G8: 0 | H8: 0 | I8: NECOMPLETAT | J8: a | K8: …...... | L8: …......
A9: 3 | B9: {=_xlfn._xlws.FILTER(Sheet1!A8:K868,Sheet1!A8:A868=RANDBETWEEN(1,861),"Fatal ERROR, this PC will explode in about 1 minute")} -> 309 | C9: La instalaţiile electrice de putere de joasă tensiune, densitatea maximă de curent admisă în regim de scurtă durată la pornire este de: | D9: 35 A/mm2 pentru conductoare de aluminiu | E9: 20 A/mm2 pentru conductoare de cupru | F9: 20 A/mm2 pentru conductoare de aluminiu | G9: 0 | H9: 0 | I9: NECOMPLETAT | J9: …...... | K9: …...... | L9: c
A10: 4 | B10: {=_xlfn._xlws.FILTER(Sheet1!A9:K869,Sheet1!A9:A869=RANDBETWEEN(1,861),"Fatal ERROR, this PC will explode in about 1 minute")} -> 457 | C10: În cazul consumatorilor racordaţi direct la reţeaua de joasă tensiune a distribuitorului, pornirea directă a motoarelor trifazate se admite pentru o putere de până la: | D10: 4 kW | E10: 5,5 kW | F10: 7,5 kW | G10: 0 | H10: 0 | I10: NECOMPLETAT | J10: …...... | K10: b | L10: …......
A11: 5 | B11: {=_xlfn._xlws.FILTER(Sheet1!A10:K870,Sheet1!A10:A870=RANDBETWEEN(1,861),"Fatal ERROR, this PC will explode in about 1 minute")} -> 801 | C11: Prevederile standardului de performanţă pentru serviciul de distribuţie nu se aplică în situaţii de: | D11: Forţă majoră | E11: Evenimente accidentale determinate de angajaţii operatorului de distribuţie | F11: condiţii meteorologice deosebite | G11: 0 | H11: 0 | I11: NECOMPLETAT | J11: a | K11: …...... | L11: …......
A12: 6 | B12: {=_xlfn._xlws.FILTER(Sheet1!A11:K871,Sheet1!A11:A871=RANDBETWEEN(1,861),"Fatal ERROR, this PC will explode in about 1 minute")} -> 311 | C12: La pozarea cablurilor de branşament pe stâlpii reţelelor electrice aeriene: | D12: pentru protecţia împotriva deteriorărilor mecanice se poate prevedea introducerea cablurilor în tub metalic pe o porţiune de 2m deasupra solului | E12: pentru protecţia împotriva deteriorărilor mecanice se poate prevedea introducerea cablurilor în tub din PVC pe o porţiune de 1 m deasupra solului | F12: reglementările nu prevăd în această situaţie măsuri de protecţie împotriva deteriorărilor mecanice | G12: 0 | H12: 0 | I12: NECOMPLETAT | J12: a | K12: …...... | L12: …......
A13: 7 | B13: {=_xlfn._xlws.FILTER(Sheet1!A12:K872,Sheet1!A12:A872=RANDBETWEEN(1,861),"Fatal ERROR, this PC will explode in about 1 minute")} -> 223 | C13: Transformatoarele de măsurare de curent: | D13: pot fi racordate în circuitul primar cu înfăşurarea secundara deschisa | E13: pot fi lăsate în exploatare cu înfăşurarea secundara deschisa | F13: nu pot fi racordate in circuitul primar cu înfăşurarea secundara deschisa | G13: 0 | H13: 0 | I13: NECOMPLETAT | J13: …...... | K13: …...... | L13: c
A14: 8 | B14: {=_xlfn._xlws.FILTER(Sheet1!A13:K873,Sheet1!A13:A873=RANDBETWEEN(1,861),"Fatal ERROR, this PC will explode in about 1 minute")} -> 417 | C14: Curentul de scurtcircuit reprezintă: | D14: curentul nominal admisibil | E14: supracurentul rezultat dintr-un scurtcircuit datorat unei conectări incorecte într-un circuit electric | F14: numai supracurentul rezultat în cazul dintr-un scurtcircuit datorat unui defect | G14: 0 | H14: 0 | I14: NECOMPLETAT | J14: …...... | K14: b | L14: …......
A15: 9 | B15: {=_xlfn._xlws.FILTER(Sheet1!A14:K874,Sheet1!A14:A874=RANDBETWEEN(1,861),"Fatal ERROR, this PC will explode in about 1 minute")} -> 628 | C15: Prevederile normativului I 7 – 2011 se aplică la proiectarea, execuţia şi exploatarea instalaţiilor electrice aferente: | D15: clădirilor prefabricate; | E15: minelor şi carierelor | F15: depozitelor de materiale pirotehnice şi explozive | G15: 0 | H15: 0 | I15: NECOMPLETAT | J15: a | K15: …...... | L15: …......
A16: 10 | B16: {=_xlfn._xlws.FILTER(Sheet1!A15:K875,Sheet1!A15:A875=RANDBETWEEN(1,861),"Fatal ERROR, this PC will explode in about 1 minute")} -> 178 | C16: Puterea electrică reactivă: | D16: permite definirea limitelor de utilizare ale unui aparat electric | E16: produce transformarea energiei electrice în energie mecanică | F16: este variaţia în timp a energiei magnetice şi electrice | G16: 0 | H16: 0 | I16: NECOMPLETAT | J16: …...... | K16: …...... | L16: c
A17: 11 | B17: {=_xlfn._xlws.FILTER(Sheet1!A16:K876,Sheet1!A16:A876=RANDBETWEEN(1,861),"Fatal ERROR, this PC will explode in about 1 minute")} -> 718 | C17: Punctele de măsurare din subcategoria C3 sunt puncte de măsurare dotate cu grupuri de măsurare: | D17: capabile să asigure date de măsurare la intervale de 60 de minute şi transmiterea bidirecţională a acestora la sistemul central de gestiune a datelor de măsurare la fiecare 24 de ore | E17: capabile să asigure date de măsurare la intervale de 15 minute şi transmiterea bidirecţională a acestora la sistemul central de gestiune a datelor de măsurare la fiecare 15 minute | F17: cu citire locală | G17: 0 | H17: 0 | I17: NECOMPLETAT | J17: …...... | K17: …...... | L17: c
A18: 12 | B18: {=_xlfn._xlws.FILTER(Sheet1!A17:K877,Sheet1!A17:A877=RANDBETWEEN(1,861),"Fatal ERROR, this PC will explode in about 1 minute")} -> 817 | C18: Contractul de distribuție se poate încheia între operatorul de distribuție și | D18: furnizorul clientului final, întotdeauna | E18: clientul final, în anumite situaţii | F18: furnizor şi clientul final | G18: 0 | H18: 0 | I18: NECOMPLETAT | J18: a | K18: …...... | L18: …......
... A31: 25 | B31: {=_xlfn._xlws.FILTER(Sheet1!A30:K890,Sheet1!A30:A890=RANDBETWEEN(1,861),"Fatal ERROR, this PC will explode in about 1 minute")} -> 722 | C31: O persoană care deţinea în proprietate sau în folosinţă o reţea electrică de distribuţie proprie la data intrării în vigoare Legii nr,123/2012: | D31: nu are obligaţii privind asigurarea accesului la reţea | E31: este obligată să asigure accesul la reţea numai pentru producători de energie electrică din surse regenerabile | F31: este obligată să asigure accesul la reţea, conform reglementărilor autorităţii competente | G31: 0 | H31: 0 | I31: NECOMPLETAT | J31: …...... | K31: …...... | L31: c

Sheet Sheet2
G2: RESPUNS INITIAL | H2: RASPUNS NOU
A3: 193 | B3: Carcasa unei celule electrice | C3: asigură numai protecţia persoanelor împotriva atingerii accidentale a pieselor aflate sub tensiune în funcţionare normală sau a pieselor în mişcare din interiorul învelişului; | D3: asigură protecţia echipamentului electric împotriva pătrunderii corpurilor străine şi a umezelii; | E3: asigură protecţia echipamentului electric împotriva supratensiunilor. | G3: A | H3: B
A4: 207 | B4: Comparativ cu un transformator, autotransformatorul are tensiunea de scurtcircuit: | C4: mai mare | D4: egală | E4: mai mică | G4: A | H4: C
A5: 210 | B5: Spaţiul ocupat de o instalaţie capsulată depinde în principal de: | C5: curentul nominal al legăturilor electrice; | D5: mediul de stingere a arcului electric; | E5: realizarea capsulării: capsulare tripolară sau monopolară. | G5: C | H5: B
A6: 214 | B6: Rolul conservatorului de ulei la transformatoarele de forţa este: | C6: de a asigura o suprafaţa de contact a uleiului cu aerul mai mica | D6: numai de a asigura spaţiul necesar dilatării si contractării uleiului | E6: de a face posibila umplerea cu ulei a transformatorului | G6: B | H6: C
A7: 233 | B7: Sistemul de tensiuni al unei reţele racordate la un generator electric care produce tensiuni electromotoare simetrice: | C7: este întotdeauna simetric | D7: este simetric chiar dacă fazele sunt neegal încărcate | E7: este simetric dacă fazele sunt egal încărcate | G7: A | H7: C
